Workbook

Sheet Léeme
A1: Seguimiento a Oportunidades de Mejora (OM) de la Revisión por la Dirección — consolidado
A2: Universidad de Cundinamarca · Sistemas Integrados de Gestión · generado el 14/10/2026 desde el dataset de la web (generado el 2026-10-14).
A4: Hojas
A5: Por sistema | B5: Estado vigente de cada sistema y total global (= «Todos los sistemas» en la web).
A6: Por vigencia | B6: Estado vigente por sistema y vigencia (= gráfica «Avance promedio por vigencia»).
A7: Por corte | B7: Evolución por seguimiento: solo las OM evaluadas en cada corte (= gráficas de evolución).
A8: OM | B8: Una fila por oportunidad de mejora (162). Estado, avance, cumplida, atención y vencida con fórmulas.
A9: Seguimientos | B9: Una fila por seguimiento (1012), con la observación completa (la web la recorta a 400 caracteres).
A10: Escala | B10: Escala institucional 0 · 0,5 · 1 · 1,5 · 2 con su estado y avance.
A12: Cómo se calcula cada cifra (igual que los íconos «!» de la web)
A13: Avance de una OM | B13: Última calificación ÷ 2. Escala: 0 → 0 %, 0,5 → 25 %, 1 → 50 %, 1,5 → 75 %, 2 → 100 %. Una OM nunca calificada cuenta como 0 %.
A14: Avance promedio vigente | B14: Promedio del avance de cada OM. Cada OM pesa lo mismo; por eso el total global no es el promedio de los cinco sistemas.
A15: Tasa de cierre vigente | B15: OM cumplidas (última calificación = 2) ÷ total de OM. El avance parcial no suma.
A16: Sin cerrar / Atención | B16: Sin cerrar = OM − cumplidas. Atención = las sin cerrar con última calificación 0.
A17: Vencida | B17: Fecha de entrega anterior al último corte de seguimiento de su sistema y OM no cumplida. Una entrega registrada como texto («Inmediato») no se evalúa.
A18: Evolución por corte | B18: En cada corte, promedio y tasa de cierre de solo las OM evaluadas ese día. Si un libro repite la fecha de un corte, cuenta la última columna.
A19: Estado vigente vs. por corte | B19: «Vigente» describe cómo está hoy cada OM (todas). «Por corte» describe cómo salió un seguimiento (solo las evaluadas). Por eso pueden diferir: p. ej. SGSI 89,3 % vigente vs. 87,5 % en el corte del 30-sep-2026 (4 OM).
A21: Notas sobre los datos
A22: Fuente | B22: Libros de data/ (uno por sistema) más la actualización data/13-10-2026/SISTEMAS INTEGRADOS DE GESTION.xlsx, que aporta el corte del 30-sep-2026.
A23: SGSI 2025 | B23: Se descartaron dos cortes rotulados «30 DE DICIEMBRE 2026» (fecha futura, fuera de orden). Indicación del 13-10-2026.
A24: SG-SST 2025 | B24: La última columna de la hoja SST del libro 13-10-2026 decía «30 ABRIL 2026» y es el corte del 30-sep-2026. Reemplaza la segunda columna «30 ABRIL 2026» del libro de junio; por eso la PM 7 (ausente en el libro nuevo) queda en 0.
A25: SGC 2025 en el Excel original | B25: La fila de promedios de la hoja «SGC 2025» usa SUM(G2:G12)/COUNT(G2:G12) y deja fuera las PM 12 y 13. Este consolidado y la web promedian las 13 OM.
A26: Fechas de entrega | B26: Las escritas como texto («Inmediato», «IPA 2025») quedan sin fecha y no se evalúan para vencimiento. «31/06/2026» (SGC 2025, PM 3) no es una fecha válida: queda sin fecha.
A27: Recalcular | B27: Todas las cifras de Por sistema, Por vigencia, Por corte y las columnas calculadas de OM y Seguimientos son fórmulas: si se corrige una calificación en Seguimientos, todo se recalcula.

Sheet Por sistema
A1: Estado vigente de cada sistema
A2: Última calificación de cada OM. Mismas cifras que la tabla y los KPI de «Todos los sistemas» en la web.
A4: Sigla | B4: Sistema de gestión | C4: Vigencias | D4: Último corte | E4: OM | F4: Cumplidas | G4: Sin cerrar | H4: Atención | I4: Avance promedio vigente | J4: Tasa de cierre vigente | K4: Vencidas
A5: SGC | B5: Sistema de Gestión de Calidad | C5: 2022–2025 | D5: =SUMPRODUCT(MAX((Seguimientos!$C$2:$C$1013=A5)*Seguimientos!$F$2:$F$1013)) | E5: =COUNTIF(OM!$B$2:$B$163,A5) | F5: =COUNTIFS(OM!$B$2:$B$163,A5,OM!$R$2:$R$163,"Sí") | G5: =E5-F5 | H5: =COUNTIFS(OM!$B$2:$B$163,A5,OM!$S$2:$S$163,"Sí") | I5: =AVERAGEIF(OM!$B$2:$B$163,A5,OM!$P$2:$P$163) | J5: =IF(E5=0,"",F5/E5) | K5: =COUNTIFS(OM!$B$2:$B$163,A5,OM!$T$2:$T$163,"Sí")
A6: SGA | B6: Sistema de Gestión Ambiental | C6: 2022–2025 | D6: =SUMPRODUCT(MAX((Seguimientos!$C$2:$C$1013=A6)*Seguimientos!$F$2:$F$1013)) | E6: =COUNTIF(OM!$B$2:$B$163,A6) | F6: =COUNTIFS(OM!$B$2:$B$163,A6,OM!$R$2:$R$163,"Sí") | G6: =E6-F6 | H6: =COUNTIFS(OM!$B$2:$B$163,A6,OM!$S$2:$S$163,"Sí") | I6: =AVERAGEIF(OM!$B$2:$B$163,A6,OM!$P$2:$P$163) | J6: =IF(E6=0,"",F6/E6) | K6: =COUNTIFS(OM!$B$2:$B$163,A6,OM!$T$2:$T$163,"Sí")
A7: SG-SST | B7: Seguridad y Salud en el Trabajo | C7: 2023–2025 | D7: =SUMPRODUCT(MAX((Seguimientos!$C$2:$C$1013=A7)*Seguimientos!$F$2:$F$1013)) | E7: =COUNTIF(OM!$B$2:$B$163,A7) | F7: =COUNTIFS(OM!$B$2:$B$163,A7,OM!$R$2:$R$163,"Sí") | G7: =E7-F7 | H7: =COUNTIFS(OM!$B$2:$B$163,A7,OM!$S$2:$S$163,"Sí") | I7: =AVERAGEIF(OM!$B$2:$B$163,A7,OM!$P$2:$P$163) | J7: =IF(E7=0,"",F7/E7) | K7: =COUNTIFS(OM!$B$2:$B$163,A7,OM!$T$2:$T$163,"Sí")
A8: SGSI | B8: Seguridad de la Información | C8: 2023–2025 | D8: =SUMPRODUCT(MAX((Seguimientos!$C$2:$C$1013=A8)*Seguimientos!$F$2:$F$1013)) | E8: =COUNTIF(OM!$B$2:$B$163,A8) | F8: =COUNTIFS(OM!$B$2:$B$163,A8,OM!$R$2:$R$163,"Sí") | G8: =E8-F8 | H8: =COUNTIFS(OM!$B$2:$B$163,A8,OM!$S$2:$S$163,"Sí") | I8: =AVERAGEIF(OM!$B$2:$B$163,A8,OM!$P$2:$P$163) | J8: =IF(E8=0,"",F8/E8) | K8: =COUNTIFS(OM!$B$2:$B$163,A8,OM!$T$2:$T$163,"Sí")
A9: SGAS | B9: Sistema de Gestión Antisoborno | C9: 2024–2025 | D9: =SUMPRODUCT(MAX((Seguimientos!$C$2:$C$1013=A9)*Seguimientos!$F$2:$F$1013)) | E9: =COUNTIF(OM!$B$2:$B$163,A9) | F9: =COUNTIFS(OM!$B$2:$B$163,A9,OM!$R$2:$R$163,"Sí") | G9: =E9-F9 | H9: =COUNTIFS(OM!$B$2:$B$163,A9,OM!$S$2:$S$163,"Sí") | I9: =AVERAGEIF(OM!$B$2:$B$163,A9,OM!$P$2:$P$163) | J9: =IF(E9=0,"",F9/E9) | K9: =COUNTIFS(OM!$B$2:$B$163,A9,OM!$T$2:$T$163,"Sí")
A10: Total | B10: Todos los sistemas | D10: =MAX(D5:D9) | E10: =SUM(E5:E9) | F10: =SUM(F5:F9) | G10: =SUM(G5:G9) | H10: =SUM(H5:H9) | I10: =AVERAGE(OM!$P$2:$P$163) | J10: =IF(E10=0,"",F10/E10) | K10: =SUM(K5:K9)
A12: Avance promedio vigente: promedio de (última calificación ÷ 2) de cada OM; una nunca calificada cuenta como 0 %.
A13: Total: promedia todas las OM juntas (cada OM pesa lo mismo), igual que el KPI «Avance promedio global vigente».
A14: Tasa de cierre vigente: OM cumplidas (última calificación = 2) ÷ total de OM.
A15: Atención: OM sin cerrar con última calificación 0. Sin cerrar = OM − cumplidas.
A16: Vencidas: fecha de entrega anterior al último corte del sistema y OM no cumplida.

Sheet Por vigencia
A1: Estado vigente por sistema y vigencia
A2: Mismas cifras que la gráfica «Avance promedio por vigencia de la RXD» de cada tablero.
A4: Sistema | B4: Vigencia | C4: OM | D4: Cumplidas | E4: Sin cerrar | F4: Avance promedio vigente | G4: Tasa de cierre vigente
A5: SGC | B5: 2022 | C5: =COUNTIFS(OM!$B$2:$B$163,A5,OM!$D$2:$D$163,B5) | D5: =COUNTIFS(OM!$B$2:$B$163,A5,OM!$D$2:$D$163,B5,OM!$R$2:$R$163,"Sí") | E5: =C5-D5 | F5: =AVERAGEIFS(OM!$P$2:$P$163,OM!$B$2:$B$163,A5,OM!$D$2:$D$163,B5) | G5: =IF(C5=0,"",D5/C5)
A6: SGC | B6: 2023 | C6: =COUNTIFS(OM!$B$2:$B$163,A6,OM!$D$2:$D$163,B6) | D6: =COUNTIFS(OM!$B$2:$B$163,A6,OM!$D$2:$D$163,B6,OM!$R$2:$R$163,"Sí") | E6: =C6-D6 | F6: =AVERAGEIFS(OM!$P$2:$P$163,OM!$B$2:$B$163,A6,OM!$D$2:$D$163,B6) | G6: =IF(C6=0,"",D6/C6)
A7: SGC | B7: 2024 | C7: =COUNTIFS(OM!$B$2:$B$163,A7,OM!$D$2:$D$163,B7) | D7: =COUNTIFS(OM!$B$2:$B$163,A7,OM!$D$2:$D$163,B7,OM!$R$2:$R$163,"Sí") | E7: =C7-D7 | F7: =AVERAGEIFS(OM!$P$2:$P$163,OM!$B$2:$B$163,A7,OM!$D$2:$D$163,B7) | G7: =IF(C7=0,"",D7/C7)
A8: SGC | B8: 2025 | C8: =COUNTIFS(OM!$B$2:$B$163,A8,OM!$D$2:$D$163,B8) | D8: =COUNTIFS(OM!$B$2:$B$163,A8,OM!$D$2:$D$163,B8,OM!$R$2:$R$163,"Sí") | E8: =C8-D8 | F8: =AVERAGEIFS(OM!$P$2:$P$163,OM!$B$2:$B$163,A8,OM!$D$2:$D$163,B8) | G8: =IF(C8=0,"",D8/C8)
A9: SGA | B9: 2022 | C9: =COUNTIFS(OM!$B$2:$B$163,A9,OM!$D$2:$D$163,B9) | D9: =COUNTIFS(OM!$B$2:$B$163,A9,OM!$D$2:$D$163,B9,OM!$R$2:$R$163,"Sí") | E9: =C9-D9 | F9: =AVERAGEIFS(OM!$P$2:$P$163,OM!$B$2:$B$163,A9,OM!$D$2:$D$163,B9) | G9: =IF(C9=0,"",D9/C9)
A10: SGA | B10: 2023 | C10: =COUNTIFS(OM!$B$2:$B$163,A10,OM!$D$2:$D$163,B10) | D10: =COUNTIFS(OM!$B$2:$B$163,A10,OM!$D$2:$D$163,B10,OM!$R$2:$R$163,"Sí") | E10: =C10-D10 | F10: =AVERAGEIFS(OM!$P$2:$P$163,OM!$B$2:$B$163,A10,OM!$D$2:$D$163,B10) | G10: =IF(C10=0,"",D10/C10)
A11: SGA | B11: 2024 | C11: =COUNTIFS(OM!$B$2:$B$163,A11,OM!$D$2:$D$163,B11) | D11: =COUNTIFS(OM!$B$2:$B$163,A11,OM!$D$2:$D$163,B11,OM!$R$2:$R$163,"Sí") | E11: =C11-D11 | F11: =AVERAGEIFS(OM!$P$2:$P$163,OM!$B$2:$B$163,A11,OM!$D$2:$D$163,B11) | G11: =IF(C11=0,"",D11/C11)
A12: SGA | B12: 2025 | C12: =COUNTIFS(OM!$B$2:$B$163,A12,OM!$D$2:$D$163,B12) | D12: =COUNTIFS(OM!$B$2:$B$163,A12,OM!$D$2:$D$163,B12,OM!$R$2:$R$163,"Sí") | E12: =C12-D12 | F12: =AVERAGEIFS(OM!$P$2:$P$163,OM!$B$2:$B$163,A12,OM!$D$2:$D$163,B12) | G12: =IF(C12=0,"",D12/C12)
A13: SG-SST | B13: 2023 | C13: =COUNTIFS(OM!$B$2:$B$163,A13,OM!$D$2:$D$163,B13) | D13: =COUNTIFS(OM!$B$2:$B$163,A13,OM!$D$2:$D$163,B13,OM!$R$2:$R$163,"Sí") | E13: =C13-D13 | F13: =AVERAGEIFS(OM!$P$2:$P$163,OM!$B$2:$B$163,A13,OM!$D$2:$D$163,B13) | G13: =IF(C13=0,"",D13/C13)
A14: SG-SST | B14: 2024 | C14: =COUNTIFS(OM!$B$2:$B$163,A14,OM!$D$2:$D$163,B14) | D14: =COUNTIFS(OM!$B$2:$B$163,A14,OM!$D$2:$D$163,B14,OM!$R$2:$R$163,"Sí") | E14: =C14-D14 | F14: =AVERAGEIFS(OM!$P$2:$P$163,OM!$B$2:$B$163,A14,OM!$D$2:$D$163,B14) | G14: =IF(C14=0,"",D14/C14)
A15: SG-SST | B15: 2025 | C15: =COUNTIFS(OM!$B$2:$B$163,A15,OM!$D$2:$D$163,B15) | D15: =COUNTIFS(OM!$B$2:$B$163,A15,OM!$D$2:$D$163,B15,OM!$R$2:$R$163,"Sí") | E15: =C15-D15 | F15: =AVERAGEIFS(OM!$P$2:$P$163,OM!$B$2:$B$163,A15,OM!$D$2:$D$163,B15) | G15: =IF(C15=0,"",D15/C15)
A16: SGSI | B16: 2023 | C16: =COUNTIFS(OM!$B$2:$B$163,A16,OM!$D$2:$D$163,B16) | D16: =COUNTIFS(OM!$B$2:$B$163,A16,OM!$D$2:$D$163,B16,OM!$R$2:$R$163,"Sí") | E16: =C16-D16 | F16: =AVERAGEIFS(OM!$P$2:$P$163,OM!$B$2:$B$163,A16,OM!$D$2:$D$163,B16) | G16: =IF(C16=0,"",D16/C16)
... A20: SGAS | B20: 2025 | C20: =COUNTIFS(OM!$B$2:$B$163,A20,OM!$D$2:$D$163,B20) | D20: =COUNTIFS(OM!$B$2:$B$163,A20,OM!$D$2:$D$163,B20,OM!$R$2:$R$163,"Sí") | E20: =C20-D20 | F20: =AVERAGEIFS(OM!$P$2:$P$163,OM!$B$2:$B$163,A20,OM!$D$2:$D$163,B20) | G20: =IF(C20=0,"",D20/C20)

Sheet Por corte
A1: Evolución por seguimiento
A2: En cada corte cuentan solo las OM evaluadas ese día. Mismas cifras que las gráficas de evolución (una línea por vigencia) y que la fila de promedios de cada hoja del libro de seguimiento.
A4: Sistema | B4: Vigencia | C4: Fecha de corte | D4: OM evaluadas | E4: Cumplidas | F4: Avance promedio | G4: Tasa de cierre
A5: SGC | B5: 2022 | C5: 45133 | D5: =COUNTIFS(Seguimientos!$C$2:$C$1013,A5,Seguimientos!$D$2:$D$1013,B5,Seguimientos!$F$2:$F$1013,C5,Seguimientos!$J$2:$J$1013,1) | E5: =COUNTIFS(Seguimientos!$C$2:$C$1013,A5,Seguimientos!$D$2:$D$1013,B5,Seguimientos!$F$2:$F$1013,C5,Seguimientos!$J$2:$J$1013,1,Seguimientos!$H$2:$H$1013,2) | F5: =IF(D5=0,"",AVERAGEIFS(Seguimientos!$I$2:$I$1013,Seguimientos!$C$2:$C$1013,A5,Seguimientos!$D$2:$D$1013,B5,Seguimientos!$F$2:$F$1013,C5,Seguimientos!$J$2:$J$1013,1)) | G5: =IF(D5=0,"",E5/D5)
A6: SGC | B6: 2022 | C6: 45245 | D6: =COUNTIFS(Seguimientos!$C$2:$C$1013,A6,Seguimientos!$D$2:$D$1013,B6,Seguimientos!$F$2:$F$1013,C6,Seguimientos!$J$2:$J$1013,1) | E6: =COUNTIFS(Seguimientos!$C$2:$C$1013,A6,Seguimientos!$D$2:$D$1013,B6,Seguimientos!$F$2:$F$1013,C6,Seguimientos!$J$2:$J$1013,1,Seguimientos!$H$2:$H$1013,2) | F6: =IF(D6=0,"",AVERAGEIFS(Seguimientos!$I$2:$I$1013,Seguimientos!$C$2:$C$1013,A6,Seguimientos!$D$2:$D$1013,B6,Seguimientos!$F$2:$F$1013,C6,Seguimientos!$J$2:$J$1013,1)) | G6: =IF(D6=0,"",E6/D6)
A7: SGC | B7: 2022 | C7: 45405 | D7: =COUNTIFS(Seguimientos!$C$2:$C$1013,A7,Seguimientos!$D$2:$D$1013,B7,Seguimientos!$F$2:$F$1013,C7,Seguimientos!$J$2:$J$1013,1) | E7: =COUNTIFS(Seguimientos!$C$2:$C$1013,A7,Seguimientos!$D$2:$D$1013,B7,Seguimientos!$F$2:$F$1013,C7,Seguimientos!$J$2:$J$1013,1,Seguimientos!$H$2:$H$1013,2) | F7: =IF(D7=0,"",AVERAGEIFS(Seguimientos!$I$2:$I$1013,Seguimientos!$C$2:$C$1013,A7,Seguimientos!$D$2:$D$1013,B7,Seguimientos!$F$2:$F$1013,C7,Seguimientos!$J$2:$J$1013,1)) | G7: =IF(D7=0,"",E7/D7)
A8: SGC | B8: 2022 | C8: 45497 | D8: =COUNTIFS(Seguimientos!$C$2:$C$1013,A8,Seguimientos!$D$2:$D$1013,B8,Seguimientos!$F$2:$F$1013,C8,Seguimientos!$J$2:$J$1013,1) | E8: =COUNTIFS(Seguimientos!$C$2:$C$1013,A8,Seguimientos!$D$2:$D$1013,B8,Seguimientos!$F$2:$F$1013,C8,Seguimientos!$J$2:$J$1013,1,Seguimientos!$H$2:$H$1013,2) | F8: =IF(D8=0,"",AVERAGEIFS(Seguimientos!$I$2:$I$1013,Seguimientos!$C$2:$C$1013,A8,Seguimientos!$D$2:$D$1013,B8,Seguimientos!$F$2:$F$1013,C8,Seguimientos!$J$2:$J$1013,1)) | G8: =IF(D8=0,"",E8/D8)
A9: SGC | B9: 2022 | C9: 45583 | D9: =COUNTIFS(Seguimientos!$C$2:$C$1013,A9,Seguimientos!$D$2:$D$1013,B9,Seguimientos!$F$2:$F$1013,C9,Seguimientos!$J$2:$J$1013,1) | E9: =COUNTIFS(Seguimientos!$C$2:$C$1013,A9,Seguimientos!$D$2:$D$1013,B9,Seguimientos!$F$2:$F$1013,C9,Seguimientos!$J$2:$J$1013,1,Seguimientos!$H$2:$H$1013,2) | F9: =IF(D9=0,"",AVERAGEIFS(Seguimientos!$I$2:$I$1013,Seguimientos!$C$2:$C$1013,A9,Seguimientos!$D$2:$D$1013,B9,Seguimientos!$F$2:$F$1013,C9,Seguimientos!$J$2:$J$1013,1)) | G9: =IF(D9=0,"",E9/D9)
A10: SGC | B10: 2022 | C10: 45777 | D10: =COUNTIFS(Seguimientos!$C$2:$C$1013,A10,Seguimientos!$D$2:$D$1013,B10,Seguimientos!$F$2:$F$1013,C10,Seguimientos!$J$2:$J$1013,1) | E10: =COUNTIFS(Seguimientos!$C$2:$C$1013,A10,Seguimientos!$D$2:$D$1013,B10,Seguimientos!$F$2:$F$1013,C10,Seguimientos!$J$2:$J$1013,1,Seguimientos!$H$2:$H$1013,2) | F10: =IF(D10=0,"",AVERAGEIFS(Seguimientos!$I$2:$I$1013,Seguimientos!$C$2:$C$1013,A10,Seguimientos!$D$2:$D$1013,B10,Seguimientos!$F$2:$F$1013,C10,Seguimientos!$J$2:$J$1013,1)) | G10: =IF(D10=0,"",E10/D10)
A11: SGC | B11: 2022 | C11: 45838 | D11: =COUNTIFS(Seguimientos!$C$2:$C$1013,A11,Seguimientos!$D$2:$D$1013,B11,Seguimientos!$F$2:$F$1013,C11,Seguimientos!$J$2:$J$1013,1) | E11: =COUNTIFS(Seguimientos!$C$2:$C$1013,A11,Seguimientos!$D$2:$D$1013,B11,Seguimientos!$F$2:$F$1013,C11,Seguimientos!$J$2:$J$1013,1,Seguimientos!$H$2:$H$1013,2) | F11: =IF(D11=0,"",AVERAGEIFS(Seguimientos!$I$2:$I$1013,Seguimientos!$C$2:$C$1013,A11,Seguimientos!$D$2:$D$1013,B11,Seguimientos!$F$2:$F$1013,C11,Seguimientos!$J$2:$J$1013,1)) | G11: =IF(D11=0,"",E11/D11)
A12: SGC | B12: 2022 | C12: 45930 | D12: =COUNTIFS(Seguimientos!$C$2:$C$1013,A12,Seguimientos!$D$2:$D$1013,B12,Seguimientos!$F$2:$F$1013,C12,Seguimientos!$J$2:$J$1013,1) | E12: =COUNTIFS(Seguimientos!$C$2:$C$1013,A12,Seguimientos!$D$2:$D$1013,B12,Seguimientos!$F$2:$F$1013,C12,Seguimientos!$J$2:$J$1013,1,Seguimientos!$H$2:$H$1013,2) | F12: =IF(D12=0,"",AVERAGEIFS(Seguimientos!$I$2:$I$1013,Seguimientos!$C$2:$C$1013,A12,Seguimientos!$D$2:$D$1013,B12,Seguimientos!$F$2:$F$1013,C12,Seguimientos!$J$2:$J$1013,1)) | G12: =IF(D12=0,"",E12/D12)
A13: SGC | B13: 2023 | C13: 45405 | D13: =COUNTIFS(Seguimientos!$C$2:$C$1013,A13,Seguimientos!$D$2:$D$1013,B13,Seguimientos!$F$2:$F$1013,C13,Seguimientos!$J$2:$J$1013,1) | E13: =COUNTIFS(Seguimientos!$C$2:$C$1013,A13,Seguimientos!$D$2:$D$1013,B13,Seguimientos!$F$2:$F$1013,C13,Seguimientos!$J$2:$J$1013,1,Seguimientos!$H$2:$H$1013,2) | F13: =IF(D13=0,"",AVERAGEIFS(Seguimientos!$I$2:$I$1013,Seguimientos!$C$2:$C$1013,A13,Seguimientos!$D$2:$D$1013,B13,Seguimientos!$F$2:$F$1013,C13,Seguimientos!$J$2:$J$1013,1)) | G13: =IF(D13=0,"",E13/D13)
A14: SGC | B14: 2023 | C14: 45497 | D14: =COUNTIFS(Seguimientos!$C$2:$C$1013,A14,Seguimientos!$D$2:$D$1013,B14,Seguimientos!$F$2:$F$1013,C14,Seguimientos!$J$2:$J$1013,1) | E14: =COUNTIFS(Seguimientos!$C$2:$C$1013,A14,Seguimientos!$D$2:$D$1013,B14,Seguimientos!$F$2:$F$1013,C14,Seguimientos!$J$2:$J$1013,1,Seguimientos!$H$2:$H$1013,2) | F14: =IF(D14=0,"",AVERAGEIFS(Seguimientos!$I$2:$I$1013,Seguimientos!$C$2:$C$1013,A14,Seguimientos!$D$2:$D$1013,B14,Seguimientos!$F$2:$F$1013,C14,Seguimientos!$J$2:$J$1013,1)) | G14: =IF(D14=0,"",E14/D14)
A15: SGC | B15: 2023 | C15: 45583 | D15: =COUNTIFS(Seguimientos!$C$2:$C$1013,A15,Seguimientos!$D$2:$D$1013,B15,Seguimientos!$F$2:$F$1013,C15,Seguimientos!$J$2:$J$1013,1) | E15: =COUNTIFS(Seguimientos!$C$2:$C$1013,A15,Seguimientos!$D$2:$D$1013,B15,Seguimientos!$F$2:$F$1013,C15,Seguimientos!$J$2:$J$1013,1,Seguimientos!$H$2:$H$1013,2) | F15: =IF(D15=0,"",AVERAGEIFS(Seguimientos!$I$2:$I$1013,Seguimientos!$C$2:$C$1013,A15,Seguimientos!$D$2:$D$1013,B15,Seguimientos!$F$2:$F$1013,C15,Seguimientos!$J$2:$J$1013,1)) | G15: =IF(D15=0,"",E15/D15)
A16: SGC | B16: 2023 | C16: 45777 | D16: =COUNTIFS(Seguimientos!$C$2:$C$1013,A16,Seguimientos!$D$2:$D$1013,B16,Seguimientos!$F$2:$F$1013,C16,Seguimientos!$J$2:$J$1013,1) | E16: =COUNTIFS(Seguimientos!$C$2:$C$1013,A16,Seguimientos!$D$2:$D$1013,B16,Seguimientos!$F$2:$F$1013,C16,Seguimientos!$J$2:$J$1013,1,Seguimientos!$H$2:$H$1013,2) | F16: =IF(D16=0,"",AVERAGEIFS(Seguimientos!$I$2:$I$1013,Seguimientos!$C$2:$C$1013,A16,Seguimientos!$D$2:$D$1013,B16,Seguimientos!$F$2:$F$1013,C16,Seguimientos!$J$2:$J$1013,1)) | G16: =IF(D16=0,"",E16/D16)
... A90: SGAS | B90: 2025 | C90: 46295 | D90: =COUNTIFS(Seguimientos!$C$2:$C$1013,A90,Seguimientos!$D$2:$D$1013,B90,Seguimientos!$F$2:$F$1013,C90,Seguimientos!$J$2:$J$1013,1) | E90: =COUNTIFS(Seguimientos!$C$2:$C$1013,A90,Seguimientos!$D$2:$D$1013,B90,Seguimientos!$F$2:$F$1013,C90,Seguimientos!$J$2:$J$1013,1,Seguimientos!$H$2:$H$1013,2) | F90: =IF(D90=0,"",AVERAGEIFS(Seguimientos!$I$2:$I$1013,Seguimientos!$C$2:$C$1013,A90,Seguimientos!$D$2:$D$1013,B90,Seguimientos!$F$2:$F$1013,C90,Seguimientos!$J$2:$J$1013,1)) | G90: =IF(D90=0,"",E90/D90)

Sheet OM
A1: ID OM | B1: Sistema | C1: Nombre del sistema | D1: Vigencia | E1: PM N° | F1: Oportunidad de mejora | G1: Responsable | H1: Áreas | I1: Entregable | J1: Entrega comprometida (texto) | K1: Fecha de entrega | L1: Seguimientos | M1: N.º último calificado | N1: Fecha último corte calificado | O1: Última calificación | P1: Avance vigente | Q1: Estado vigente | R1: Cumplida | S1: Atención (sin avance) | T1: Vencida
A2: sgc-2022-1 | B2: SGC | C2: Sistema de Gestión de Calidad | D2: 2022 | E2: 1 | F2: Se evidencia un comportamiento estable de las salidas no conformes entre 2021-2022; sin embargo, en los seguimientos no se cuenta con el aseguramiento de cubrir a la totalidad de las partes interesadas. | G2: Oficina de calidad – procesos a los que aplica SNC | H2: Calidad | I2: Actualizar los procedimientos e instructivos de salidas no conformes de los procesos, para incluir actividades de verificación de conformidad posterior a su tratamiento. | J2: 45078 | K2: 45078 | L2: =COUNTIF(Seguimientos!$A$2:$A$1013,A2) | M2: =SUMPRODUCT(MAX((Seguimientos!$A$2:$A$1013=A2)*(Seguimientos!$H$2:$H$1013<>"")*Seguimientos!$B$2:$B$1013)) | N2: =IF(M2=0,"",INDEX(Seguimientos!$F$2:$F$1013,MATCH(A2&"|"&M2,Seguimientos!$K$2:$K$1013,0))) | O2: =IF(M2=0,0,INDEX(Seguimientos!$H$2:$H$1013,MATCH(A2&"|"&M2,Seguimientos!$K$2:$K$1013,0))) | P2: =O2/2 | Q2: =INDEX(Escala!$B$2:$B$6,MATCH(O2,Escala!$A$2:$A$6,0)) | R2: =IF(O2=2,"Sí","No") | S2: =IF(O2=0,"Sí","No") | T2: =IF(AND(ISNUMBER(K2),O2<2),IF(K2<INDEX('Por sistema'!$D$5:$D$9,MATCH(B2,'Por sistema'!$A$5:$A$9,0)),"Sí","No"),"No")
A3: sgc-2022-2 | B3: SGC | C3: Sistema de Gestión de Calidad | D3: 2022 | E3: 2 | F3: Generar contrato de auditoria integrada de SIG en una sola auditoria. (Interna y tercera parte) | G3: Coordinación de Calidad | H3: Calidad | I3: Generar el contrato de auditorías Integrales en el primer semestre para los sistemas de gestión. | J3: 45078 | K3: 45078 | L3: =COUNTIF(Seguimientos!$A$2:$A$1013,A3) | M3: =SUMPRODUCT(MAX((Seguimientos!$A$2:$A$1013=A3)*(Seguimientos!$H$2:$H$1013<>"")*Seguimientos!$B$2:$B$1013)) | N3: =IF(M3=0,"",INDEX(Seguimientos!$F$2:$F$1013,MATCH(A3&"|"&M3,Seguimientos!$K$2:$K$1013,0))) | O3: =IF(M3=0,0,INDEX(Seguimientos!$H$2:$H$1013,MATCH(A3&"|"&M3,Seguimientos!$K$2:$K$1013,0))) | P3: =O3/2 | Q3: =INDEX(Escala!$B$2:$B$6,MATCH(O3,Escala!$A$2:$A$6,0)) | R3: =IF(O3=2,"Sí","No") | S3: =IF(O3=0,"Sí","No") | T3: =IF(AND(ISNUMBER(K3),O3<2),IF(K3<INDEX('Por sistema'!$D$5:$D$9,MATCH(B3,'Por sistema'!$A$5:$A$9,0)),"Sí","No"),"No")
A4: sgc-2022-3 | B4: SGC | C4: Sistema de Gestión de Calidad | D4: 2022 | E4: 3 | F4: La sistematización de la reevaluación al proveedor de bienes y servicios en la plataforma Integradoc. | G4: Dirección de Bienes y Servicios - Oficina de Calidad | H4: Calidad, Bienes, Servicios y Compras | I4: Sistematizar del formato de reevaluación de proveedores. | J4: 45078 | K4: 45078 | L4: =COUNTIF(Seguimientos!$A$2:$A$1013,A4) | M4: =SUMPRODUCT(MAX((Seguimientos!$A$2:$A$1013=A4)*(Seguimientos!$H$2:$H$1013<>"")*Seguimientos!$B$2:$B$1013)) | N4: =IF(M4=0,"",INDEX(Seguimientos!$F$2:$F$1013,MATCH(A4&"|"&M4,Seguimientos!$K$2:$K$1013,0))) | O4: =IF(M4=0,0,INDEX(Seguimientos!$H$2:$H$1013,MATCH(A4&"|"&M4,Seguimientos!$K$2:$K$1013,0))) | P4: =O4/2 | Q4: =INDEX(Escala!$B$2:$B$6,MATCH(O4,Escala!$A$2:$A$6,0)) | R4: =IF(O4=2,"Sí","No") | S4: =IF(O4=0,"Sí","No") | T4: =IF(AND(ISNUMBER(K4),O4<2),IF(K4<INDEX('Por sistema'!$D$5:$D$9,MATCH(B4,'Por sistema'!$A$5:$A$9,0)),"Sí","No"),"No")
A5: sgc-2022-4 | B5: SGC | C5: Sistema de Gestión de Calidad | D5: 2022 | E5: 4 | F5: La Universidad en aras de garantizar procesos pre-contractuales, contractuales y post-contractuales con selección objetiva y transparencia, crea el procedimiento ABSP18 para supervisores e interventores, donde se establecen actividades y responsables dentro del mismo, junto con requisitos y condiciones generales para el desarrollo del procedimiento. | G5: Dirección de Bienes y Servicios (Oficina de Compras) - Oficina de Calidad | H5: Calidad, Bienes, Servicios y Compras | I5: Realizar un diagnostico de los procedimientos de contratación y supervisión para generar los ajustes necesarios que conlleven a optimizar el proceso. | J5: 45261 | K5: 45261 | L5: =COUNTIF(Seguimientos!$A$2:$A$1013,A5) | M5: =SUMPRODUCT(MAX((Seguimientos!$A$2:$A$1013=A5)*(Seguimientos!$H$2:$H$1013<>"")*Seguimientos!$B$2:$B$1013)) | N5: =IF(M5=0,"",INDEX(Seguimientos!$F$2:$F$1013,MATCH(A5&"|"&M5,Seguimientos!$K$2:$K$1013,0))) | O5: =IF(M5=0,0,INDEX(Seguimientos!$H$2:$H$1013,MATCH(A5&"|"&M5,Seguimientos!$K$2:$K$1013,0))) | P5: =O5/2 | Q5: =INDEX(Escala!$B$2:$B$6,MATCH(O5,Escala!$A$2:$A$6,0)) | R5: =IF(O5=2,"Sí","No") | S5: =IF(O5=0,"Sí","No") | T5: =IF(AND(ISNUMBER(K5),O5<2),IF(K5<INDEX('Por sistema'!$D$5:$D$9,MATCH(B5,'Por sistema'!$A$5:$A$9,0)),"Sí","No"),"No")
A6: sgc-2022-4-sn1u5ppt | B6: SGC | C6: Sistema de Gestión de Calidad | D6: 2022 | E6: 4 | F6: Mejora continua en la documentación del proceso de compras | G6: Dirección de Bienes y Servicios (Oficina de Compras) - Oficina de Calidad | H6: Calidad, Bienes, Servicios y Compras | J6: 45261 | K6: 45261 | L6: =COUNTIF(Seguimientos!$A$2:$A$1013,A6) | M6: =SUMPRODUCT(MAX((Seguimientos!$A$2:$A$1013=A6)*(Seguimientos!$H$2:$H$1013<>"")*Seguimientos!$B$2:$B$1013)) | N6: =IF(M6=0,"",INDEX(Seguimientos!$F$2:$F$1013,MATCH(A6&"|"&M6,Seguimientos!$K$2:$K$1013,0))) | O6: =IF(M6=0,0,INDEX(Seguimientos!$H$2:$H$1013,MATCH(A6&"|"&M6,Seguimientos!$K$2:$K$1013,0))) | P6: =O6/2 | Q6: =INDEX(Escala!$B$2:$B$6,MATCH(O6,Escala!$A$2:$A$6,0)) | R6: =IF(O6=2,"Sí","No") | S6: =IF(O6=0,"Sí","No") | T6: =IF(AND(ISNUMBER(K6),O6<2),IF(K6<INDEX('Por sistema'!$D$5:$D$9,MATCH(B6,'Por sistema'!$A$5:$A$9,0)),"Sí","No"),"No")
A7: sgc-2022-5 | B7: SGC | C7: Sistema de Gestión de Calidad | D7: 2022 | E7: 5 | F7: Cambiar metodología de riesgos y oportunidades | G7: Coordinación de calidad y dirección de Control Interno | H7: Control Interno, Calidad | I7: Ajustar la metodología de gestión de los riesgos y las oportunidades, con el fin de incrementar la rigurosidad de las calificaciones y el seguimiento. | J7: 45261 | K7: 45261 | L7: =COUNTIF(Seguimientos!$A$2:$A$1013,A7) | M7: =SUMPRODUCT(MAX((Seguimientos!$A$2:$A$1013=A7)*(Seguimientos!$H$2:$H$1013<>"")*Seguimientos!$B$2:$B$1013)) | N7: =IF(M7=0,"",INDEX(Seguimientos!$F$2:$F$1013,MATCH(A7&"|"&M7,Seguimientos!$K$2:$K$1013,0))) | O7: =IF(M7=0,0,INDEX(Seguimientos!$H$2:$H$1013,MATCH(A7&"|"&M7,Seguimientos!$K$2:$K$1013,0))) | P7: =O7/2 | Q7: =INDEX(Escala!$B$2:$B$6,MATCH(O7,Escala!$A$2:$A$6,0)) | R7: =IF(O7=2,"Sí","No") | S7: =IF(O7=0,"Sí","No") | T7: =IF(AND(ISNUMBER(K7),O7<2),IF(K7<INDEX('Por sistema'!$D$5:$D$9,MATCH(B7,'Por sistema'!$A$5:$A$9,0)),"Sí","No"),"No")
A8: sgc-2022-6 | B8: SGC | C8: Sistema de Gestión de Calidad | D8: 2022 | E8: 6 | F8: De la vigencia 2019 a la vigencia 2022 se presentan en total 26 planes de mejoramiento con categoría oportunidades de mejora propias de las cuales 18 se encuentran cerradas, 7 en ejecución y una en estado agregado. En relación con el impacto se concluye que las oportunidades de mejora propias han ayudado en un 35% mejorar métodos para estructurar roles, responsabilidades y tareas, seguida de un 27% en mejoras tecnológicas que permitan reducir tiempos de operación seguido de un 23% en la mejora de controles internos que aseguren resultados alineados a la estrategia y finalmente mejoras en los métodos de trabajo con un 15%. | G8: Coordinación de calidad y Control interno | H8: Control Interno, Calidad | I8: Determinar la ruta crítica de procedimientos que tengan el mayor porcentaje de no conformidades reiterativas para generar revisión y ajuste a sus controles con enfoque preventivo desde la metodología de riesgos y oportunidades. | J8: 45261 | K8: 45261 | L8: =COUNTIF(Seguimientos!$A$2:$A$1013,A8) | M8: =SUMPRODUCT(MAX((Seguimientos!$A$2:$A$1013=A8)*(Seguimientos!$H$2:$H$1013<>"")*Seguimientos!$B$2:$B$1013)) | N8: =IF(M8=0,"",INDEX(Seguimientos!$F$2:$F$1013,MATCH(A8&"|"&M8,Seguimientos!$K$2:$K$1013,0))) | O8: =IF(M8=0,0,INDEX(Seguimientos!$H$2:$H$1013,MATCH(A8&"|"&M8,Seguimientos!$K$2:$K$1013,0))) | P8: =O8/2 | Q8: =INDEX(Escala!$B$2:$B$6,MATCH(O8,Escala!$A$2:$A$6,0)) | R8: =IF(O8=2,"Sí","No") | S8: =IF(O8=0,"Sí","No") | T8: =IF(AND(ISNUMBER(K8),O8<2),IF(K8<INDEX('Por sistema'!$D$5:$D$9,MATCH(B8,'Por sistema'!$A$5:$A$9,0)),"Sí","No"),"No")
A9: sgc-2022-7 | B9: SGC | C9: Sistema de Gestión de Calidad | D9: 2022 | E9: 7 | F9: El incumplimiento en los métodos de trabajo es la mayor causa en no conformidades; sin embargo, es la solución de mejora que más se da en todas las oportunidades de mejora revisadas, se propone generar una ruta crítica de procedimientos que tengan el mayor porcentaje de no conformidades reiterativas para generar revisión a sus controles. | G9: Coordinación de Calidad Dirección de Control Interno | H9: Control Interno, Calidad | I9: Generar una ruta crítica de procedimientos y/o procesos que tengan el mayor porcentaje de no conformidades reiterativas y generar ajustes a los controles operacionales. | J9: 45261 | K9: 45261 | L9: =COUNTIF(Seguimientos!$A$2:$A$1013,A9) | M9: =SUMPRODUCT(MAX((Seguimientos!$A$2:$A$1013=A9)*(Seguimientos!$H$2:$H$1013<>"")*Seguimientos!$B$2:$B$1013)) | N9: =IF(M9=0,"",INDEX(Seguimientos!$F$2:$F$1013,MATCH(A9&"|"&M9,Seguimientos!$K$2:$K$1013,0))) | O9: =IF(M9=0,0,INDEX(Seguimientos!$H$2:$H$1013,MATCH(A9&"|"&M9,Seguimientos!$K$2:$K$1013,0))) | P9: =O9/2 | Q9: =INDEX(Escala!$B$2:$B$6,MATCH(O9,Escala!$A$2:$A$6,0)) | R9: =IF(O9=2,"Sí","No") | S9: =IF(O9=0,"Sí","No") | T9: =IF(AND(ISNUMBER(K9),O9<2),IF(K9<INDEX('Por sistema'!$D$5:$D$9,MATCH(B9,'Por sistema'!$A$5:$A$9,0)),"Sí","No"),"No")
A10: sgc-2023-1 | B10: SGC | C10: Sistema de Gestión de Calidad | D10: 2023 | E10: 1 | F10: Hacer un segundo seguimiento a las decisiones pendientes de años anteriores por parte de Control Interno antes de que llegue la auditoría de certificación. | G10: Control Interno | H10: Control Interno | I10: Informe o matriz de seguimiento a las decisiones pendientes de vigencias anteriores. | J10: Inmediato | L10: =COUNTIF(Seguimientos!$A$2:$A$1013,A10) | M10: =SUMPRODUCT(MAX((Seguimientos!$A$2:$A$1013=A10)*(Seguimientos!$H$2:$H$1013<>"")*Seguimientos!$B$2:$B$1013)) | N10: =IF(M10=0,"",INDEX(Seguimientos!$F$2:$F$1013,MATCH(A10&"|"&M10,Seguimientos!$K$2:$K$1013,0))) | O10: =IF(M10=0,0,INDEX(Seguimientos!$H$2:$H$1013,MATCH(A10&"|"&M10,Seguimientos!$K$2:$K$1013,0))) | P10: =O10/2 | Q10: =INDEX(Escala!$B$2:$B$6,MATCH(O10,Escala!$A$2:$A$6,0)) | R10: =IF(O10=2,"Sí","No") | S10: =IF(O10=0,"Sí","No") | T10: =IF(AND(ISNUMBER(K10),O10<2),IF(K10<INDEX('Por sistema'!$D$5:$D$9,MATCH(B10,'Por sistema'!$A$5:$A$9,0)),"Sí","No"),"No")
A11: sgc-2023-2 | B11: SGC | C11: Sistema de Gestión de Calidad | D11: 2023 | E11: 2 | F11: Coordinar una mesa de trabajo desde la Dirección de Planeación junto con la Dirección de Sistemas, la Dirección de Bienes y Servicios, y la Jefatura de Recursos Físicos, a más tardar el día 10 de noviembre para atender lo antes posible lo relacionado con el Data Center. | G11: Dirección de Planeación | H11: Planeación Institucional | I11: Registro de asistencia de la sesión de trabajo o grabación de la reunión. | J11: 45240 | K11: 45240 | L11: =COUNTIF(Seguimientos!$A$2:$A$1013,A11) | M11: =SUMPRODUCT(MAX((Seguimientos!$A$2:$A$1013=A11)*(Seguimientos!$H$2:$H$1013<>"")*Seguimientos!$B$2:$B$1013)) | N11: =IF(M11=0,"",INDEX(Seguimientos!$F$2:$F$1013,MATCH(A11&"|"&M11,Seguimientos!$K$2:$K$1013,0))) | O11: =IF(M11=0,0,INDEX(Seguimientos!$H$2:$H$1013,MATCH(A11&"|"&M11,Seguimientos!$K$2:$K$1013,0))) | P11: =O11/2 | Q11: =INDEX(Escala!$B$2:$B$6,MATCH(O11,Escala!$A$2:$A$6,0)) | R11: =IF(O11=2,"Sí","No") | S11: =IF(O11=0,"Sí","No") | T11: =IF(AND(ISNUMBER(K11),O11<2),IF(K11<INDEX('Por sistema'!$D$5:$D$9,MATCH(B11,'Por sistema'!$A$5:$A$9,0)),"Sí","No"),"No")
A12: sgc-2023-3 | B12: SGC | C12: Sistema de Gestión de Calidad | D12: 2023 | E12: 3 | F12: Dar continuidad a las mesas de trabajo, capacitaciones virtuales y jornadas de sensibilización, dirigidas a las áreas solicitantes. | G12: Jefatura de Compras | H12: Bienes, Servicios y Compras | I12: Registro de asistencia de la sesión de trabajo o grabación de la reunión. | J12: Una capacitación antes del 17-11-2023, una en febrero de 2024 y otra en julio de 2024. | L12: =COUNTIF(Seguimientos!$A$2:$A$1013,A12) | M12: =SUMPRODUCT(MAX((Seguimientos!$A$2:$A$1013=A12)*(Seguimientos!$H$2:$H$1013<>"")*Seguimientos!$B$2:$B$1013)) | N12: =IF(M12=0,"",INDEX(Seguimientos!$F$2:$F$1013,MATCH(A12&"|"&M12,Seguimientos!$K$2:$K$1013,0))) | O12: =IF(M12=0,0,INDEX(Seguimientos!$H$2:$H$1013,MATCH(A12&"|"&M12,Seguimientos!$K$2:$K$1013,0))) | P12: =O12/2 | Q12: =INDEX(Escala!$B$2:$B$6,MATCH(O12,Escala!$A$2:$A$6,0)) | R12: =IF(O12=2,"Sí","No") | S12: =IF(O12=0,"Sí","No") | T12: =IF(AND(ISNUMBER(K12),O12<2),IF(K12<INDEX('Por sistema'!$D$5:$D$9,MATCH(B12,'Por sistema'!$A$5:$A$9,0)),"Sí","No"),"No")
A13: sgc-2023-4 | B13: SGC | C13: Sistema de Gestión de Calidad | D13: 2023 | E13: 4 | F13: Socializar a las áreas con el respaldo de las vicerrectorías y la Secretaría General, las demostraciones correspondientes a los sistemas de información académico, financiero y administrativo. | G13: Dirección de Sistemas y Tecnología | H13: Sistemas y Tecnología | I13: Registro de asistencia de las sesiones de trabajo y socializaciones a las diferentes áreas. | J13: 45275 | K13: 45275 | L13: =COUNTIF(Seguimientos!$A$2:$A$1013,A13) | M13: =SUMPRODUCT(MAX((Seguimientos!$A$2:$A$1013=A13)*(Seguimientos!$H$2:$H$1013<>"")*Seguimientos!$B$2:$B$1013)) | N13: =IF(M13=0,"",INDEX(Seguimientos!$F$2:$F$1013,MATCH(A13&"|"&M13,Seguimientos!$K$2:$K$1013,0))) | O13: =IF(M13=0,0,INDEX(Seguimientos!$H$2:$H$1013,MATCH(A13&"|"&M13,Seguimientos!$K$2:$K$1013,0))) | P13: =O13/2 | Q13: =INDEX(Escala!$B$2:$B$6,MATCH(O13,Escala!$A$2:$A$6,0)) | R13: =IF(O13=2,"Sí","No") | S13: =IF(O13=0,"Sí","No") | T13: =IF(AND(ISNUMBER(K13),O13<2),IF(K13<INDEX('Por sistema'!$D$5:$D$9,MATCH(B13,'Por sistema'!$A$5:$A$9,0)),"Sí","No"),"No")
A14: sgc-2023-5 | B14: SGC | C14: Sistema de Gestión de Calidad | D14: 2023 | E14: 5 | F14: Solicitar a los procesos que están presentando indicadores con incumplimiento y que actualmente no cuentan con planes de mejoramiento, generar para cada uno de estos, un plan de mejoramiento con el fin de fortalecer los resultados y dar un cierre eficaz a corte de diciembre 2023. En caso de que cuenten con plan de mejoramiento, este se debe revisar y ajustar según corresponda. | G14: Oficina de Calidad - Líderes de los procesos | H14: Calidad | I14: Planes de mejoramiento generados y cargados en el aplicativo correspondiente por los procesos para el fortalecimiento de los resultados de indicadores de gestión. | J14: 45291 | K14: 45291 | L14: =COUNTIF(Seguimientos!$A$2:$A$1013,A14) | M14: =SUMPRODUCT(MAX((Seguimientos!$A$2:$A$1013=A14)*(Seguimientos!$H$2:$H$1013<>"")*Seguimientos!$B$2:$B$1013)) | N14: =IF(M14=0,"",INDEX(Seguimientos!$F$2:$F$1013,MATCH(A14&"|"&M14,Seguimientos!$K$2:$K$1013,0))) | O14: =IF(M14=0,0,INDEX(Seguimientos!$H$2:$H$1013,MATCH(A14&"|"&M14,Seguimientos!$K$2:$K$1013,0))) | P14: =O14/2 | Q14: =INDEX(Escala!$B$2:$B$6,MATCH(O14,Escala!$A$2:$A$6,0)) | R14: =IF(O14=2,"Sí","No") | S14: =IF(O14=0,"Sí","No") | T14: =IF(AND(ISNUMBER(K14),O14<2),IF(K14<INDEX('Por sistema'!$D$5:$D$9,MATCH(B14,'Por sistema'!$A$5:$A$9,0)),"Sí","No"),"No")
A15: sgc-2023-6 | B15: SGC | C15: Sistema de Gestión de Calidad | D15: 2023 | E15: 6 | F15: Actualizar el Plan Estratégico de Seguridad Vial y sus anexos. | G15: Oficina de Recursos Físicos | H15: Recursos Físicos | I15: Plan Estratégico de Seguridad Vial y sus anexos actualizados. | J15: diciembre 2023 | L15: =COUNTIF(Seguimientos!$A$2:$A$1013,A15) | M15: =SUMPRODUCT(MAX((Seguimientos!$A$2:$A$1013=A15)*(Seguimientos!$H$2:$H$1013<>"")*Seguimientos!$B$2:$B$1013)) | N15: =IF(M15=0,"",INDEX(Seguimientos!$F$2:$F$1013,MATCH(A15&"|"&M15,Seguimientos!$K$2:$K$1013,0))) | O15: =IF(M15=0,0,INDEX(Seguimientos!$H$2:$H$1013,MATCH(A15&"|"&M15,Seguimientos!$K$2:$K$1013,0))) | P15: =O15/2 | Q15: =INDEX(Escala!$B$2:$B$6,MATCH(O15,Escala!$A$2:$A$6,0)) | R15: =IF(O15=2,"Sí","No") | S15: =IF(O15=0,"Sí","No") | T15: =IF(AND(ISNUMBER(K15),O15<2),IF(K15<INDEX('Por sistema'!$D$5:$D$9,MATCH(B15,'Por sistema'!$A$5:$A$9,0)),"Sí","No"),"No")
A16: sgc-2023-7 | B16: SGC | C16: Sistema de Gestión de Calidad | D16: 2023 | E16: 7 | F16: Como parte de las acciones de los resultados de la encuesta de satisfacción, se debe establecer un plan de trabajo con aquellos procesos que no alcanzaron un nivel de satisfacción de conformidad con el indicador propuesto, con el fin de evidenciar mejora con la segunda encuesta que se está aplicando en este momento. Responsable. | G16: Dirección de Planeación | H16: Planeación Institucional | I16: Cronograma del plan de trabajo con los procesos que no hayan alcanzado el nivel propuesto por el indicador. | J16: diciembre 2023 | L16: =COUNTIF(Seguimientos!$A$2:$A$1013,A16) | M16: =SUMPRODUCT(MAX((Seguimientos!$A$2:$A$1013=A16)*(Seguimientos!$H$2:$H$1013<>"")*Seguimientos!$B$2:$B$1013)) | N16: =IF(M16=0,"",INDEX(Seguimientos!$F$2:$F$1013,MATCH(A16&"|"&M16,Seguimientos!$K$2:$K$1013,0))) | O16: =IF(M16=0,0,INDEX(Seguimientos!$H$2:$H$1013,MATCH(A16&"|"&M16,Seguimientos!$K$2:$K$1013,0))) | P16: =O16/2 | Q16: =INDEX(Escala!$B$2:$B$6,MATCH(O16,Escala!$A$2:$A$6,0)) | R16: =IF(O16=2,"Sí","No") | S16: =IF(O16=0,"Sí","No") | T16: =IF(AND(ISNUMBER(K16),O16<2),IF(K16<INDEX('Por sistema'!$D$5:$D$9,MATCH(B16,'Por sistema'!$A$5:$A$9,0)),"Sí","No"),"No")
A17: sgc-2023-8 | B17: SGC | C17: Sistema de Gestión de Calidad | D17: 2023 | E17: 8 | F17: Realizar el cierre de los objetivos establecidos en la Resolución 096 de 2021, con corte a diciembre 2023 y llevar el análisis de los resultados al comité SAC para la toma de decisiones que sea pertinente. | G17: Oficina de Calidad | H17: Calidad | I17: Informe de cierre de los objetivos establecidos en la Resolución 096 de 2021, con corte a diciembre 2023 y acta de la sesión de comité SAC con el punto del informe socializado. | J17: 45351 | K17: 45351 | L17: =COUNTIF(Seguimientos!$A$2:$A$1013,A17) | M17: =SUMPRODUCT(MAX((Seguimientos!$A$2:$A$1013=A17)*(Seguimientos!$H$2:$H$1013<>"")*Seguimientos!$B$2:$B$1013)) | N17: =IF(M17=0,"",INDEX(Seguimientos!$F$2:$F$1013,MATCH(A17&"|"&M17,Seguimientos!$K$2:$K$1013,0))) | O17: =IF(M17=0,0,INDEX(Seguimientos!$H$2:$H$1013,MATCH(A17&"|"&M17,Seguimientos!$K$2:$K$1013,0))) | P17: =O17/2 | Q17: =INDEX(Escala!$B$2:$B$6,MATCH(O17,Escala!$A$2:$A$6,0)) | R17: =IF(O17=2,"Sí","No") | S17: =IF(O17=0,"Sí","No") | T17: =IF(AND(ISNUMBER(K17),O17<2),IF(K17<INDEX('Por sistema'!$D$5:$D$9,MATCH(B17,'Por sistema'!$A$5:$A$9,0)),"Sí","No"),"No")
A18: sgc-2023-9 | B18: SGC | C18: Sistema de Gestión de Calidad | D18: 2023 | E18: 9 | F18: Documentar los lineamientos de control de acceso universitario a partir de la consolidación de un procedimiento de ingreso a planta física que actualice los lineamientos establecidos en la Resolución 307 de 2008. | G18: Oficina de Recursos Físicos | H18: Recursos Físicos | I18: Procedimiento actualizado de acuerdo a la resolución 307/2008 y cargado en el MOD. | J18: febrero 2024 | L18: =COUNTIF(Seguimientos!$A$2:$A$1013,A18) | M18: =SUMPRODUCT(MAX((Seguimientos!$A$2:$A$1013=A18)*(Seguimientos!$H$2:$H$1013<>"")*Seguimientos!$B$2:$B$1013)) | N18: =IF(M18=0,"",INDEX(Seguimientos!$F$2:$F$1013,MATCH(A18&"|"&M18,Seguimientos!$K$2:$K$1013,0))) | O18: =IF(M18=0,0,INDEX(Seguimientos!$H$2:$H$1013,MATCH(A18&"|"&M18,Seguimientos!$K$2:$K$1013,0))) | P18: =O18/2 | Q18: =INDEX(Escala!$B$2:$B$6,MATCH(O18,Escala!$A$2:$A$6,0)) | R18: =IF(O18=2,"Sí","No") | S18: =IF(O18=0,"Sí","No") | T18: =IF(AND(ISNUMBER(K18),O18<2),IF(K18<INDEX('Por sistema'!$D$5:$D$9,MATCH(B18,'Por sistema'!$A$5:$A$9,0)),"Sí","No"),"No")
A19: sgc-2023-10 | B19: SGC | C19: Sistema de Gestión de Calidad | D19: 2023 | E19: 10 | F19: Establecer las condiciones técnicas de los teléfonos para determinar si están o no en uso. Responsable. | G19: Dirección de Sistemas y Tecnología | H19: Sistemas y Tecnología | I19: Informe de condiciones técnicas de los teléfonos. | J19: febrero 2024 | L19: =COUNTIF(Seguimientos!$A$2:$A$1013,A19) | M19: =SUMPRODUCT(MAX((Seguimientos!$A$2:$A$1013=A19)*(Seguimientos!$H$2:$H$1013<>"")*Seguimientos!$B$2:$B$1013)) | N19: =IF(M19=0,"",INDEX(Seguimientos!$F$2:$F$1013,MATCH(A19&"|"&M19,Seguimientos!$K$2:$K$1013,0))) | O19: =IF(M19=0,0,INDEX(Seguimientos!$H$2:$H$1013,MATCH(A19&"|"&M19,Seguimientos!$K$2:$K$1013,0))) | P19: =O19/2 | Q19: =INDEX(Escala!$B$2:$B$6,MATCH(O19,Escala!$A$2:$A$6,0)) | R19: =IF(O19=2,"Sí","No") | S19: =IF(O19=0,"Sí","No") | T19: =IF(AND(ISNUMBER(K19),O19<2),IF(K19<INDEX('Por sistema'!$D$5:$D$9,MATCH(B19,'Por sistema'!$A$5:$A$9,0)),"Sí","No"),"No")
A20: sgc-2023-11 | B20: SGC | C20: Sistema de Gestión de Calidad | D20: 2023 | E20: 11 | F20: Implementar una metodología de planificación de prácticas académicas y/o experiencias formativas, con el fin de reducir los impactos administrativos / académicos que implican la reprogramación o cancelación de las mismas. | G20: Comité de prácticas académicas | H20: Apoyo y Desarrollo Académico | I20: Documento con la metodología a aplicar o procedimiento e instructivo actualizado. | J20: 45381 | K20: 45381 | L20: =COUNTIF(Seguimientos!$A$2:$A$1013,A20) | M20: =SUMPRODUCT(MAX((Seguimientos!$A$2:$A$1013=A20)*(Seguimientos!$H$2:$H$1013<>"")*Seguimientos!$B$2:$B$1013)) | N20: =IF(M20=0,"",INDEX(Seguimientos!$F$2:$F$1013,MATCH(A20&"|"&M20,Seguimientos!$K$2:$K$1013,0))) | O20: =IF(M20=0,0,INDEX(Seguimientos!$H$2:$H$1013,MATCH(A20&"|"&M20,Seguimientos!$K$2:$K$1013,0))) | P20: =O20/2 | Q20: =INDEX(Escala!$B$2:$B$6,MATCH(O20,Escala!$A$2:$A$6,0)) | R20: =IF(O20=2,"Sí","No") | S20: =IF(O20=0,"Sí","No") | T20: =IF(AND(ISNUMBER(K20),O20<2),IF(K20<INDEX('Por sistema'!$D$5:$D$9,MATCH(B20,'Por sistema'!$A$5:$A$9,0)),"Sí","No"),"No")
A21: sgc-2023-12 | B21: SGC | C21: Sistema de Gestión de Calidad | D21: 2023 | E21: 12 | F21: Implementar una metodología de diagnóstico y priorización de necesidades de elementos educativos, con el fin de atender las necesidades que históricamente ha requerido la academia. | G21: Unidad de Apoyo Académico | H21: Apoyo y Desarrollo Académico | I21: Metodología implementada por medio de instructivo o procedimiento. Herramienta tecnológica o digitalización de la metodología en mención, si aplica. | J21: 45381 | K21: 45381 | L21: =COUNTIF(Seguimientos!$A$2:$A$1013,A21) | M21: =SUMPRODUCT(MAX((Seguimientos!$A$2:$A$1013=A21)*(Seguimientos!$H$2:$H$1013<>"")*Seguimientos!$B$2:$B$1013)) | N21: =IF(M21=0,"",INDEX(Seguimientos!$F$2:$F$1013,MATCH(A21&"|"&M21,Seguimientos!$K$2:$K$1013,0))) | O21: =IF(M21=0,0,INDEX(Seguimientos!$H$2:$H$1013,MATCH(A21&"|"&M21,Seguimientos!$K$2:$K$1013,0))) | P21: =O21/2 | Q21: =INDEX(Escala!$B$2:$B$6,MATCH(O21,Escala!$A$2:$A$6,0)) | R21: =IF(O21=2,"Sí","No") | S21: =IF(O21=0,"Sí","No") | T21: =IF(AND(ISNUMBER(K21),O21<2),IF(K21<INDEX('Por sistema'!$D$5:$D$9,MATCH(B21,'Por sistema'!$A$5:$A$9,0)),"Sí","No"),"No")
A22: sgc-2023-13 | B22: SGC | C22: Sistema de Gestión de Calidad | D22: 2023 | E22: 13 | F22: Incluir en el inventario de necesidades para priorización la mejora del aplicativo de SNC, en cuanto al paso posterior de seguimiento al cumplimiento de la recuperación de sesiones de formación. | G22: Oficina de Calidad - Sistemas y Tecnología | H22: Sistemas y Tecnología, Calidad | I22: Cronograma de priorización de la Dirección de Sistemas y Tecnología, donde se evidencia la inclusión de la mejora del aplicativo SNC. | J22: 45381 | K22: 45381 | L22: =COUNTIF(Seguimientos!$A$2:$A$1013,A22) | M22: =SUMPRODUCT(MAX((Seguimientos!$A$2:$A$1013=A22)*(Seguimientos!$H$2:$H$1013<>"")*Seguimientos!$B$2:$B$1013)) | N22: =IF(M22=0,"",INDEX(Seguimientos!$F$2:$F$1013,MATCH(A22&"|"&M22,Seguimientos!$K$2:$K$1013,0))) | O22: =IF(M22=0,0,INDEX(Seguimientos!$H$2:$H$1013,MATCH(A22&"|"&M22,Seguimientos!$K$2:$K$1013,0))) | P22: =O22/2 | Q22: =INDEX(Escala!$B$2:$B$6,MATCH(O22,Escala!$A$2:$A$6,0)) | R22: =IF(O22=2,"Sí","No") | S22: =IF(O22=0,"Sí","No") | T22: =IF(AND(ISNUMBER(K22),O22<2),IF(K22<INDEX('Por sistema'!$D$5:$D$9,MATCH(B22,'Por sistema'!$A$5:$A$9,0)),"Sí","No"),"No")
A23: sgc-2023-14 | B23: SGC | C23: Sistema de Gestión de Calidad | D23: 2023 | E23: 14 | F23: Generar estrategias para el fortalecimiento de las competencias relacionadas con la transparencia y la orientación al usuario y al ciudadano, así como fortalecer las metodologías de carácter digital y tecnológico para generar programas de formación y capacitación del personal. | G23: Dirección de Talento Humano | H23: Talento Humano | I23: Socialización de las estrategias a implementar para los dos casos y actualización documental si aplica. | J23: marzo 2024 | L23: =COUNTIF(Seguimientos!$A$2:$A$1013,A23) | M23: =SUMPRODUCT(MAX((Seguimientos!$A$2:$A$1013=A23)*(Seguimientos!$H$2:$H$1013<>"")*Seguimientos!$B$2:$B$1013)) | N23: =IF(M23=0,"",INDEX(Seguimientos!$F$2:$F$1013,MATCH(A23&"|"&M23,Seguimientos!$K$2:$K$1013,0))) | O23: =IF(M23=0,0,INDEX(Seguimientos!$H$2:$H$1013,MATCH(A23&"|"&M23,Seguimientos!$K$2:$K$1013,0))) | P23: =O23/2 | Q23: =INDEX(Escala!$B$2:$B$6,MATCH(O23,Escala!$A$2:$A$6,0)) | R23: =IF(O23=2,"Sí","No") | S23: =IF(O23=0,"Sí","No") | T23: =IF(AND(ISNUMBER(K23),O23<2),IF(K23<INDEX('Por sistema'!$D$5:$D$9,MATCH(B23,'Por sistema'!$A$5:$A$9,0)),"Sí","No"),"No")
A24: sgc-2023-15 | B24: SGC | C24: Sistema de Gestión de Calidad | D24: 2023 | E24: 15 | F24: Consolidar el plan estratégico de tecnologías de la información (redes, servicios, servidores, plataformas, etc.) para atender de manera adecuada la oferta académica virtual que la Universidad está proyectando. | G24: Dirección de Sistemas y Tecnología | H24: Sistemas y Tecnología | I24: Plan estratégico de tecnologías de la información (redes, servicios, servidores, plataformas, etc.) enfocado en la oferta académica virtual. | J24: marzo 2024 | L24: =COUNTIF(Seguimientos!$A$2:$A$1013,A24) | M24: =SUMPRODUCT(MAX((Seguimientos!$A$2:$A$1013=A24)*(Seguimientos!$H$2:$H$1013<>"")*Seguimientos!$B$2:$B$1013)) | N24: =IF(M24=0,"",INDEX(Seguimientos!$F$2:$F$1013,MATCH(A24&"|"&M24,Seguimientos!$K$2:$K$1013,0))) | O24: =IF(M24=0,0,INDEX(Seguimientos!$H$2:$H$1013,MATCH(A24&"|"&M24,Seguimientos!$K$2:$K$1013,0))) | P24: =O24/2 | Q24: =INDEX(Escala!$B$2:$B$6,MATCH(O24,Escala!$A$2:$A$6,0)) | R24: =IF(O24=2,"Sí","No") | S24: =IF(O24=0,"Sí","No") | T24: =IF(AND(ISNUMBER(K24),O24<2),IF(K24<INDEX('Por sistema'!$D$5:$D$9,MATCH(B24,'Por sistema'!$A$5:$A$9,0)),"Sí","No"),"No")
A25: sgc-2023-16 | B25: SGC | C25: Sistema de Gestión de Calidad | D25: 2023 | E25: 16 | F25: Reasignación de espacio físico para el archivo de talento humano. | G25: Planeación Institucional - Archivo y Correspondencia - Talento Humano | H25: Planeación Institucional, Talento Humano, Archivo y Correspondencia | I25: Documento o acto administrativo con la reasignación de espacio físico para el archivo de talento humano. | J25: Trimestre I 2024 | L25: =COUNTIF(Seguimientos!$A$2:$A$1013,A25) | M25: =SUMPRODUCT(MAX((Seguimientos!$A$2:$A$1013=A25)*(Seguimientos!$H$2:$H$1013<>"")*Seguimientos!$B$2:$B$1013)) | N25: =IF(M25=0,"",INDEX(Seguimientos!$F$2:$F$1013,MATCH(A25&"|"&M25,Seguimientos!$K$2:$K$1013,0))) | O25: =IF(M25=0,0,INDEX(Seguimientos!$H$2:$H$1013,MATCH(A25&"|"&M25,Seguimientos!$K$2:$K$1013,0))) | P25: =O25/2 | Q25: =INDEX(Escala!$B$2:$B$6,MATCH(O25,Escala!$A$2:$A$6,0)) | R25: =IF(O25=2,"Sí","No") | S25: =IF(O25=0,"Sí","No") | T25: =IF(AND(ISNUMBER(K25),O25<2),IF(K25<INDEX('Por sistema'!$D$5:$D$9,MATCH(B25,'Por sistema'!$A$5:$A$9,0)),"Sí","No"),"No")
A26: sgc-2023-17 | B26: SGC | C26: Sistema de Gestión de Calidad | D26: 2023 | E26: 17 | F26: Hacer un estudio de tiempos y movimientos con la Oficina de Calidad de los trámites internos para el proceso de investigación, articulado con el área administrativa. | G26: Dirección de Investigación - Oficina de Calidad | H26: Calidad, Investigación Universitaria | I26: Informe de estudio de tiempos y movimientos de los trámites internos para el proceso de investigación, articulado con el área administrativa. | J26: IPA 2024 | L26: =COUNTIF(Seguimientos!$A$2:$A$1013,A26) | M26: =SUMPRODUCT(MAX((Seguimientos!$A$2:$A$1013=A26)*(Seguimientos!$H$2:$H$1013<>"")*Seguimientos!$B$2:$B$1013)) | N26: =IF(M26=0,"",INDEX(Seguimientos!$F$2:$F$1013,MATCH(A26&"|"&M26,Seguimientos!$K$2:$K$1013,0))) | O26: =IF(M26=0,0,INDEX(Seguimientos!$H$2:$H$1013,MATCH(A26&"|"&M26,Seguimientos!$K$2:$K$1013,0))) | P26: =O26/2 | Q26: =INDEX(Escala!$B$2:$B$6,MATCH(O26,Escala!$A$2:$A$6,0)) | R26: =IF(O26=2,"Sí","No") | S26: =IF(O26=0,"Sí","No") | T26: =IF(AND(ISNUMBER(K26),O26<2),IF(K26<INDEX('Por sistema'!$D$5:$D$9,MATCH(B26,'Por sistema'!$A$5:$A$9,0)),"Sí","No"),"No")
A27: sgc-2023-18 | B27: SGC | C27: Sistema de Gestión de Calidad | D27: 2023 | E27: 18 | F27: Revisar la gestión del proceso de internacionalización dado que no solamente por los resultados estadísticos de los planes de mejoramiento, sino por otros temas revisados desde la Comisión de Control Interno, denota deficiencias en la gestión de la mejora. | G27: Vicerrectoría Académica | H27: Vicerrectoría Académica | I27: Informe de seguimiento a la gestión de mejora en las actividades del proceso de internacionalización. | J27: IPA 2024 | L27: =COUNTIF(Seguimientos!$A$2:$A$1013,A27) | M27: =SUMPRODUCT(MAX((Seguimientos!$A$2:$A$1013=A27)*(Seguimientos!$H$2:$H$1013<>"")*Seguimientos!$B$2:$B$1013)) | N27: =IF(M27=0,"",INDEX(Seguimientos!$F$2:$F$1013,MATCH(A27&"|"&M27,Seguimientos!$K$2:$K$1013,0))) | O27: =IF(M27=0,0,INDEX(Seguimientos!$H$2:$H$1013,MATCH(A27&"|"&M27,Seguimientos!$K$2:$K$1013,0))) | P27: =O27/2 | Q27: =INDEX(Escala!$B$2:$B$6,MATCH(O27,Escala!$A$2:$A$6,0)) | R27: =IF(O27=2,"Sí","No") | S27: =IF(O27=0,"Sí","No") | T27: =IF(AND(ISNUMBER(K27),O27<2),IF(K27<INDEX('Por sistema'!$D$5:$D$9,MATCH(B27,'Por sistema'!$A$5:$A$9,0)),"Sí","No"),"No")
A28: sgc-2023-19 | B28: SGC | C28: Sistema de Gestión de Calidad | D28: 2023 | E28: 19 | F28: Adelantar mesas de trabajo entre la Dirección Planeación, la Dirección de Bienes y Servicios, la Oficina de Equidad y Diversidad y la Oficina de Seguridad y Salud en el Trabajo, con el fin de validar la necesidad de realizar estudios de factibilidad para el acceso a la planta física de la UDEC en el marco de la inclusión. | G28: Oficina de Recursos Físicos | H28: Recursos Físicos | I28: Registros de asistencia o grabación de las mesas de trabajo de validación de estudios de factibilidad para el acceso a la planta física de la UDEC en el marco de la inclusión. | J28: IPA 2024 | L28: =COUNTIF(Seguimientos!$A$2:$A$1013,A28) | M28: =SUMPRODUCT(MAX((Seguimientos!$A$2:$A$1013=A28)*(Seguimientos!$H$2:$H$1013<>"")*Seguimientos!$B$2:$B$1013)) | N28: =IF(M28=0,"",INDEX(Seguimientos!$F$2:$F$1013,MATCH(A28&"|"&M28,Seguimientos!$K$2:$K$1013,0))) | O28: =IF(M28=0,0,INDEX(Seguimientos!$H$2:$H$1013,MATCH(A28&"|"&M28,Seguimientos!$K$2:$K$1013,0))) | P28: =O28/2 | Q28: =INDEX(Escala!$B$2:$B$6,MATCH(O28,Escala!$A$2:$A$6,0)) | R28: =IF(O28=2,"Sí","No") | S28: =IF(O28=0,"Sí","No") | T28: =IF(AND(ISNUMBER(K28),O28<2),IF(K28<INDEX('Por sistema'!$D$5:$D$9,MATCH(B28,'Por sistema'!$A$5:$A$9,0)),"Sí","No"),"No")
A29: sgc-2023-20 | B29: SGC | C29: Sistema de Gestión de Calidad | D29: 2023 | E29: 20 | F29: Generar contenido de un curso virtual, en el cual se profundice sobre las líneas de defensa dando mayor relevancia a los temas de autocontrol, teniendo en cuenta que por las estadísticas se tiende a ser reactivo a la espera de la auditoria para mejorar. | G29: Control Interno | H29: Control Interno | I29: Curso virtual activo y en funcionamiento en aulas virtuales, MOOCs. | J29: IPA 2024 | L29: =COUNTIF(Seguimientos!$A$2:$A$1013,A29) | M29: =SUMPRODUCT(MAX((Seguimientos!$A$2:$A$1013=A29)*(Seguimientos!$H$2:$H$1013<>"")*Seguimientos!$B$2:$B$1013)) | N29: =IF(M29=0,"",INDEX(Seguimientos!$F$2:$F$1013,MATCH(A29&"|"&M29,Seguimientos!$K$2:$K$1013,0))) | O29: =IF(M29=0,0,INDEX(Seguimientos!$H$2:$H$1013,MATCH(A29&"|"&M29,Seguimientos!$K$2:$K$1013,0))) | P29: =O29/2 | Q29: =INDEX(Escala!$B$2:$B$6,MATCH(O29,Escala!$A$2:$A$6,0)) | R29: =IF(O29=2,"Sí","No") | S29: =IF(O29=0,"Sí","No") | T29: =IF(AND(ISNUMBER(K29),O29<2),IF(K29<INDEX('Por sistema'!$D$5:$D$9,MATCH(B29,'Por sistema'!$A$5:$A$9,0)),"Sí","No"),"No")
A30: sgc-2023-21 | B30: SGC | C30: Sistema de Gestión de Calidad | D30: 2023 | E30: 21 | F30: Para los temas reiterativos de No conformidad incluir estas unidades auditables para el 2024 previo estudio de nivel de riesgos. | G30: Dirección de Control Interno | H30: Control Interno | I30: Plan de auditorias con la inclusión de temas relacionados con no conformidades reiterativas. Informe de estudio de nivel de riesgos 2024. | J30: IPA 2024 | L30: =COUNTIF(Seguimientos!$A$2:$A$1013,A30) | M30: =SUMPRODUCT(MAX((Seguimientos!$A$2:$A$1013=A30)*(Seguimientos!$H$2:$H$1013<>"")*Seguimientos!$B$2:$B$1013)) | N30: =IF(M30=0,"",INDEX(Seguimientos!$F$2:$F$1013,MATCH(A30&"|"&M30,Seguimientos!$K$2:$K$1013,0))) | O30: =IF(M30=0,0,INDEX(Seguimientos!$H$2:$H$1013,MATCH(A30&"|"&M30,Seguimientos!$K$2:$K$1013,0))) | P30: =O30/2 | Q30: =INDEX(Escala!$B$2:$B$6,MATCH(O30,Escala!$A$2:$A$6,0)) | R30: =IF(O30=2,"Sí","No") | S30: =IF(O30=0,"Sí","No") | T30: =IF(AND(ISNUMBER(K30),O30<2),IF(K30<INDEX('Por sistema'!$D$5:$D$9,MATCH(B30,'Por sistema'!$A$5:$A$9,0)),"Sí","No"),"No")
A31: sgc-2023-22 | B31: SGC | C31: Sistema de Gestión de Calidad | D31: 2023 | E31: 22 | F31: Adelantar la gestión del cambio de la Resolución 088: 2023, con el fin de desagregar las funciones del PHVA de los Sistemas de Gestión. | G31: Dirección de Control Interno | H31: Control Interno | I31: Matriz de gestión del cambio y articulación de las actividades de desagregación del ciclo PHVA de los sistemas de Gestión. | J31: IPA 2024 | L31: =COUNTIF(Seguimientos!$A$2:$A$1013,A31) | M31: =SUMPRODUCT(MAX((Seguimientos!$A$2:$A$1013=A31)*(Seguimientos!$H$2:$H$1013<>"")*Seguimientos!$B$2:$B$1013)) | N31: =IF(M31=0,"",INDEX(Seguimientos!$F$2:$F$1013,MATCH(A31&"|"&M31,Seguimientos!$K$2:$K$1013,0))) | O31: =IF(M31=0,0,INDEX(Seguimientos!$H$2:$H$1013,MATCH(A31&"|"&M31,Seguimientos!$K$2:$K$1013,0))) | P31: =O31/2 | Q31: =INDEX(Escala!$B$2:$B$6,MATCH(O31,Escala!$A$2:$A$6,0)) | R31: =IF(O31=2,"Sí","No") | S31: =IF(O31=0,"Sí","No") | T31: =IF(AND(ISNUMBER(K31),O31<2),IF(K31<INDEX('Por sistema'!$D$5:$D$9,MATCH(B31,'Por sistema'!$A$5:$A$9,0)),"Sí","No"),"No")
A32: sgc-2023-23 | B32: SGC | C32: Sistema de Gestión de Calidad | D32: 2023 | E32: 23 | F32: Incluir dentro de los acuerdos de gestión de los directivos y jefes el cierre de los planes de mejoramiento como actividad de tipo institucional, o en su defecto considerarla dentro del plan de acción de la siguiente vigencia como estrategia de mejora. | G32: Dirección de Talento Humano | H32: Talento Humano | I32: Acuerdos de Gestión con la articulación de actividades de cierre de planes de mejoramiento. | J32: IPA 2024 | L32: =COUNTIF(Seguimientos!$A$2:$A$1013,A32) | M32: =SUMPRODUCT(MAX((Seguimientos!$A$2:$A$1013=A32)*(Seguimientos!$H$2:$H$1013<>"")*Seguimientos!$B$2:$B$1013)) | N32: =IF(M32=0,"",INDEX(Seguimientos!$F$2:$F$1013,MATCH(A32&"|"&M32,Seguimientos!$K$2:$K$1013,0))) | O32: =IF(M32=0,0,INDEX(Seguimientos!$H$2:$H$1013,MATCH(A32&"|"&M32,Seguimientos!$K$2:$K$1013,0))) | P32: =O32/2 | Q32: =INDEX(Escala!$B$2:$B$6,MATCH(O32,Escala!$A$2:$A$6,0)) | R32: =IF(O32=2,"Sí","No") | S32: =IF(O32=0,"Sí","No") | T32: =IF(AND(ISNUMBER(K32),O32<2),IF(K32<INDEX('Por sistema'!$D$5:$D$9,MATCH(B32,'Por sistema'!$A$5:$A$9,0)),"Sí","No"),"No")
A33: sgc-2023-24 | B33: SGC | C33: Sistema de Gestión de Calidad | D33: 2023 | E33: 24 | F33: Hacer una capacitación para dar a conocer el uso adecuado de los teléfonos. | G33: Oficina de Atención al Ciudadano | H33: Atención al Ciudadano | I33: Registros de asistencia o grabaciones de las sesiones de capacitación. | J33: abril 2024 | L33: =COUNTIF(Seguimientos!$A$2:$A$1013,A33) | M33: =SUMPRODUCT(MAX((Seguimientos!$A$2:$A$1013=A33)*(Seguimientos!$H$2:$H$1013<>"")*Seguimientos!$B$2:$B$1013)) | N33: =IF(M33=0,"",INDEX(Seguimientos!$F$2:$F$1013,MATCH(A33&"|"&M33,Seguimientos!$K$2:$K$1013,0))) | O33: =IF(M33=0,0,INDEX(Seguimientos!$H$2:$H$1013,MATCH(A33&"|"&M33,Seguimientos!$K$2:$K$1013,0))) | P33: =O33/2 | Q33: =INDEX(Escala!$B$2:$B$6,MATCH(O33,Escala!$A$2:$A$6,0)) | R33: =IF(O33=2,"Sí","No") | S33: =IF(O33=0,"Sí","No") | T33: =IF(AND(ISNUMBER(K33),O33<2),IF(K33<INDEX('Por sistema'!$D$5:$D$9,MATCH(B33,'Por sistema'!$A$5:$A$9,0)),"Sí","No"),"No")
A34: sgc-2023-25 | B34: SGC | C34: Sistema de Gestión de Calidad | D34: 2023 | E34: 25 | F34: Realizar un análisis de causas del incremento de salidas no conformes relacionadas con la inasistencia de profesores, para determinar estrategias que permitan controlar esta tendencia. | G34: Desarrollo Académico | H34: Apoyo y Desarrollo Académico | I34: Informe de Análisis causa en el incremento de salidas no conformes relacionadas con la inasistencia de profesores, con el planteamiento de las estrategias para el control de tendencias crecientes. | J34: 45442 | K34: 45442 | L34: =COUNTIF(Seguimientos!$A$2:$A$1013,A34) | M34: =SUMPRODUCT(MAX((Seguimientos!$A$2:$A$1013=A34)*(Seguimientos!$H$2:$H$1013<>"")*Seguimientos!$B$2:$B$1013)) | N34: =IF(M34=0,"",INDEX(Seguimientos!$F$2:$F$1013,MATCH(A34&"|"&M34,Seguimientos!$K$2:$K$1013,0))) | O34: =IF(M34=0,0,INDEX(Seguimientos!$H$2:$H$1013,MATCH(A34&"|"&M34,Seguimientos!$K$2:$K$1013,0))) | P34: =O34/2 | Q34: =INDEX(Escala!$B$2:$B$6,MATCH(O34,Escala!$A$2:$A$6,0)) | R34: =IF(O34=2,"Sí","No") | S34: =IF(O34=0,"Sí","No") | T34: =IF(AND(ISNUMBER(K34),O34<2),IF(K34<INDEX('Por sistema'!$D$5:$D$9,MATCH(B34,'Por sistema'!$A$5:$A$9,0)),"Sí","No"),"No")
A35: sgc-2023-26 | B35: SGC | C35: Sistema de Gestión de Calidad | D35: 2023 | E35: 26 | F35: Actualizar la Resolución No. 096 de 2021 con el fin de actualizar los lineamientos (Política) y los objetivos del sistema de gestión de la Calidad, de acuerdo con el nuevo Plan Rectoral y Plan de Desarrollo. | G35: Oficina de Calidad - trámite ante los cuerpos colegiados | H35: Calidad, Cuerpos Colegiados y Comités | I35: Resolución No. 096 de 2021 actualizada, de acuerdo a los documentos maestros para la vigencia 2024. | J35: 45473 | K35: 45473 | L35: =COUNTIF(Seguimientos!$A$2:$A$1013,A35) | M35: =SUMPRODUCT(MAX((Seguimientos!$A$2:$A$1013=A35)*(Seguimientos!$H$2:$H$1013<>"")*Seguimientos!$B$2:$B$1013)) | N35: =IF(M35=0,"",INDEX(Seguimientos!$F$2:$F$1013,MATCH(A35&"|"&M35,Seguimientos!$K$2:$K$1013,0))) | O35: =IF(M35=0,0,INDEX(Seguimientos!$H$2:$H$1013,MATCH(A35&"|"&M35,Seguimientos!$K$2:$K$1013,0))) | P35: =O35/2 | Q35: =INDEX(Escala!$B$2:$B$6,MATCH(O35,Escala!$A$2:$A$6,0)) | R35: =IF(O35=2,"Sí","No") | S35: =IF(O35=0,"Sí","No") | T35: =IF(AND(ISNUMBER(K35),O35<2),IF(K35<INDEX('Por sistema'!$D$5:$D$9,MATCH(B35,'Por sistema'!$A$5:$A$9,0)),"Sí","No"),"No")
A36: sgc-2023-27 | B36: SGC | C36: Sistema de Gestión de Calidad | D36: 2023 | E36: 27 | F36: Actualizar el Modelo de Evaluación para los gestores del conocimiento en relación con el procedimiento, la estructura de la evaluación, la plataforma para el procesamiento de la información y la aprobación del Consejo Académico. | G36: Vicerrectoría Académica - Oficina de Desarrollo Académico - EFAD | H36: Vicerrectoría Académica, Apoyo y Desarrollo Académico, Educación Virtual y EFAD | I36: Nuevo Modelo de Evaluación para los gestores del conocimiento y procedimiento actualizado. | J36: 45473 | K36: 45473 | L36: =COUNTIF(Seguimientos!$A$2:$A$1013,A36) | M36: =SUMPRODUCT(MAX((Seguimientos!$A$2:$A$1013=A36)*(Seguimientos!$H$2:$H$1013<>"")*Seguimientos!$B$2:$B$1013)) | N36: =IF(M36=0,"",INDEX(Seguimientos!$F$2:$F$1013,MATCH(A36&"|"&M36,Seguimientos!$K$2:$K$1013,0))) | O36: =IF(M36=0,0,INDEX(Seguimientos!$H$2:$H$1013,MATCH(A36&"|"&M36,Seguimientos!$K$2:$K$1013,0))) | P36: =O36/2 | Q36: =INDEX(Escala!$B$2:$B$6,MATCH(O36,Escala!$A$2:$A$6,0)) | R36: =IF(O36=2,"Sí","No") | S36: =IF(O36=0,"Sí","No") | T36: =IF(AND(ISNUMBER(K36),O36<2),IF(K36<INDEX('Por sistema'!$D$5:$D$9,MATCH(B36,'Por sistema'!$A$5:$A$9,0)),"Sí","No"),"No")
A37: sgc-2023-28 | B37: SGC | C37: Sistema de Gestión de Calidad | D37: 2023 | E37: 28 | F37: En línea con la proposición establecida dentro de la sección de Objetivos de Calidad, si estos se actualizan, es necesario reevaluar toda la batería de indicadores en el año 2024, para ajustarlos o alinearlos en coherencia con las directrices que se definan en el Plan Rectoral y el Plan de Desarrollo. | G37: Oficina de Calidad - Comité SAC - Comisión de Gestión | H37: Calidad, Cuerpos Colegiados y Comités | I37: Batería de indicadores actualizada de acuerdo con los lineamientos de los documentos maestro(Plan rectoral y Plan de acción 2024) | J37: 45473 | K37: 45473 | L37: =COUNTIF(Seguimientos!$A$2:$A$1013,A37) | M37: =SUMPRODUCT(MAX((Seguimientos!$A$2:$A$1013=A37)*(Seguimientos!$H$2:$H$1013<>"")*Seguimientos!$B$2:$B$1013)) | N37: =IF(M37=0,"",INDEX(Seguimientos!$F$2:$F$1013,MATCH(A37&"|"&M37,Seguimientos!$K$2:$K$1013,0))) | O37: =IF(M37=0,0,INDEX(Seguimientos!$H$2:$H$1013,MATCH(A37&"|"&M37,Seguimientos!$K$2:$K$1013,0))) | P37: =O37/2 | Q37: =INDEX(Escala!$B$2:$B$6,MATCH(O37,Escala!$A$2:$A$6,0)) | R37: =IF(O37=2,"Sí","No") | S37: =IF(O37=0,"Sí","No") | T37: =IF(AND(ISNUMBER(K37),O37<2),IF(K37<INDEX('Por sistema'!$D$5:$D$9,MATCH(B37,'Por sistema'!$A$5:$A$9,0)),"Sí","No"),"No")
